<?xml version="1.0"?>
<robot name="humanoid_25dof">

  <!-- ================= LINKS ================= -->
  <!-- Torso Links -->
  <link name="base_link">
    <visual><geometry><box size="0.2 0.1 0.3"/></geometry></visual>
    <collision><geometry><box size="0.2 0.1 0.3"/></geometry></collision>
    <inertial><mass value="10.0"/><inertia ixx="0.1" ixy="0" ixz="0" iyy="0.1" iyz="0" izz="0.1"/><origin xyz="0 0 0" rpy="0 0 0"/></inertial>
  </link>

  <link name="spine1_link">
    <visual><geometry><box size="0.15 0.1 0.2"/></geometry></visual>
    <collision><geometry><box size="0.15 0.1 0.2"/></geometry></collision>
    <inertial><mass value="5.0"/><inertia ixx="0.05" ixy="0" ixz="0" iyy="0.05" iyz="0" izz="0.05"/><origin xyz="0 0 0" rpy="0 0 0"/></inertial>
  </link>

  <link name="spine2_link">
    <visual><geometry><box size="0.15 0.1 0.2"/></geometry></visual>
    <collision><geometry><box size="0.15 0.1 0.2"/></geometry></collision>
    <inertial><mass value="5.0"/><inertia ixx="0.05" ixy="0" ixz="0" iyy="0.05" iyz="0" izz="0.05"/><origin xyz="0 0 0" rpy="0 0 0"/></inertial>
  </link>

  <link name="neck_link">
    <visual><geometry><box size="0.08 0.08 0.1"/></geometry></visual>
    <collision><geometry><box size="0.08 0.08 0.1"/></geometry></collision>
    <inertial><mass value="1.0"/><inertia ixx="0.01" ixy="0" ixz="0" iyy="0.01" iyz="0" izz="0.01"/><origin xyz="0 0 0" rpy="0 0 0"/></inertial>
  </link>

  <link name="head_link">
    <visual><geometry><sphere radius="0.1"/></geometry></visual>
    <collision><geometry><sphere radius="0.1"/></geometry></collision>
    <inertial><mass value="2.0"/><inertia ixx="0.02" ixy="0" ixz="0" iyy="0.02" iyz="0" izz="0.02"/><origin xyz="0 0 0" rpy="0 0 0"/></inertial>
  </link>

  <!-- Arms Left -->
  <link name="left_shoulder_link">
    <visual><geometry><box size="0.08 0.08 0.08"/></geometry></visual>
    <collision><geometry><box size="0.08 0.08 0.08"/></geometry></collision>
    <inertial><mass value="1.0"/><inertia ixx="0.01" ixy="0" ixz="0" iyy="0.01" iyz="0" izz="0.01"/><origin xyz="0 0 0" rpy="0 0 0"/></inertial>
  </link>
  <link name="left_upper_arm_link">
    <visual><geometry><cylinder radius="0.05" length="0.25"/></geometry></visual>
    <collision><geometry><cylinder radius="0.05" length="0.25"/></geometry></collision>
    <inertial><mass value="1.5"/><inertia ixx="0.015" ixy="0" ixz="0" iyy="0.015" iyz="0" izz="0.015"/><origin xyz="0 0 0" rpy="0 0 0"/></inertial>
  </link>
  <link name="left_forearm_link">
    <visual><geometry><cylinder radius="0.04" length="0.25"/></geometry></visual>
    <collision><geometry><cylinder radius="0.04" length="0.25"/></geometry></collision>
    <inertial><mass value="1.0"/><inertia ixx="0.01" ixy="0" ixz="0" iyy="0.01" iyz="0" izz="0.01"/><origin xyz="0 0 0" rpy="0 0 0"/></inertial>
  </link>
  <link name="left_hand_link">
    <visual><geometry><sphere radius="0.05"/></geometry></visual>
    <collision><geometry><sphere radius="0.05"/></geometry></collision>
    <inertial><mass value="0.5"/><inertia ixx="0.005" ixy="0" ixz="0" iyy="0.005" iyz="0" izz="0.005"/><origin xyz="0 0 0" rpy="0 0 0"/></inertial>
  </link>

  <!-- Arms Right -->
  <link name="right_shoulder_link">
    <visual><geometry><box size="0.08 0.08 0.08"/></geometry></visual>
    <collision><geometry><box size="0.08 0.08 0.08"/></geometry></collision>
    <inertial><mass value="1.0"/><inertia ixx="0.01" ixy="0" ixz="0" iyy="0.01" iyz="0" izz="0.01"/><origin xyz="0 0 0" rpy="0 0 0"/></inertial>
  </link>
  <link name="right_upper_arm_link">
    <visual><geometry><cylinder radius="0.05" length="0.25"/></geometry></visual>
    <collision><geometry><cylinder radius="0.05" length="0.25"/></geometry></collision>
    <inertial><mass value="1.5"/><inertia ixx="0.015" ixy="0" ixz="0" iyy="0.015" iyz="0" izz="0.015"/><origin xyz="0 0 0" rpy="0 0 0"/></inertial>
  </link>
  <link name="right_forearm_link">
    <visual><geometry><cylinder radius="0.04" length="0.25"/></geometry></visual>
    <collision><geometry><cylinder radius="0.04" length="0.25"/></geometry></collision>
    <inertial><mass value="1.0"/><inertia ixx="0.01" ixy="0" ixz="0" iyy="0.01" iyz="0" izz="0.01"/><origin xyz="0 0 0" rpy="0 0 0"/></inertial>
  </link>
  <link name="right_hand_link">
    <visual><geometry><sphere radius="0.05"/></geometry></visual>
    <collision><geometry><sphere radius="0.05"/></geometry></collision>
    <inertial><mass value="0.5"/><inertia ixx="0.005" ixy="0" ixz="0" iyy="0.005" iyz="0" izz="0.005"/><origin xyz="0 0 0" rpy="0 0 0"/></inertial>
  </link>

  <!-- Legs Left -->
  <link name="left_hip_link">
    <visual><geometry><box size="0.08 0.08 0.08"/></geometry></visual>
    <collision><geometry><box size="0.08 0.08 0.08"/></geometry></collision>
    <inertial><mass value="2.0"/><inertia ixx="0.02" ixy="0" ixz="0" iyy="0.02" iyz="0" izz="0.02"/><origin xyz="0 0 0" rpy="0 0 0"/></inertial>
  </link>
  <link name="left_thigh_link">
    <visual><geometry><cylinder radius="0.06" length="0.3"/></geometry></visual>
    <collision><geometry><cylinder radius="0.06" length="0.3"/></geometry></collision>
    <inertial><mass value="3.0"/><inertia ixx="0.03" ixy="0" ixz="0" iyy="0.03" iyz="0" izz="0.03"/><origin xyz="0 0 0" rpy="0 0 0"/></inertial>
  </link>
  <link name="left_shin_link">
    <visual><geometry><cylinder radius="0.05" length="0.3"/></geometry></visual>
    <collision><geometry><cylinder radius="0.05" length="0.3"/></geometry></collision>
    <inertial><mass value="2.5"/><inertia ixx="0.025" ixy="0" ixz="0" iyy="0.025" iyz="0" izz="0.025"/><origin xyz="0 0 0" rpy="0 0 0"/></inertial>
  </link>
  <link name="left_foot_link">
    <visual><geometry><box size="0.1 0.05 0.02"/></geometry></visual>
    <collision><geometry><box size="0.1 0.05 0.02"/></geometry></collision>
    <inertial><mass value="1.0"/><inertia ixx="0.01" ixy="0" ixz="0" iyy="0.01" iyz="0" izz="0.01"/><origin xyz="0 0 0" rpy="0 0 0"/></inertial>
  </link>

  <!-- Legs Right -->
  <link name="right_hip_link">
    <visual><geometry><box size="0.08 0.08 0.08"/></geometry></visual>
    <collision><geometry><box size="0.08 0.08 0.08"/></geometry></collision>
    <inertial><mass value="2.0"/><inertia ixx="0.02" ixy="0" ixz="0" iyy="0.02" iyz="0" izz="0.02"/><origin xyz="0 0 0" rpy="0 0 0"/></inertial>
  </link>
  <link name="right_thigh_link">
    <visual><geometry><cylinder radius="0.06" length="0.3"/></geometry></visual>
    <collision><geometry><cylinder radius="0.06" length="0.3"/></geometry></collision>
    <inertial><mass value="3.0"/><inertia ixx="0.03" ixy="0" ixz="0" iyy="0.03" iyz="0" izz="0.03"/><origin xyz="0 0 0" rpy="0 0 0"/></inertial>
  </link>
  <link name="right_shin_link">
    <visual><geometry><cylinder radius="0.05" length="0.3"/></geometry></visual>
    <collision><geometry><cylinder radius="0.05" length="0.3"/></geometry></collision>
    <inertial><mass value="2.5"/><inertia ixx="0.025" ixy="0" ixz="0" iyy="0.025" iyz="0" izz="0.025"/><origin xyz="0 0 0" rpy="0 0 0"/></inertial>
  </link>
  <link name="right_foot_link">
    <visual><geometry><box size="0.1 0.05 0.02"/></geometry></visual>
    <collision><geometry><box size="0.1 0.05 0.02"/></geometry></collision>
    <inertial><mass value="1.0"/><inertia ixx="0.01" ixy="0" ixz="0" iyy="0.01" iyz="0" izz="0.01"/><origin xyz="0 0 0" rpy="0 0 0"/></inertial>
  </link>

  <!-- ================= JOINTS ================= -->
  <!-- Torso -->
  <joint name="spine1_joint" type="revolute">
    <parent link="base_link"/>
    <child link="spine1_link"/>
    <origin xyz="0 0 0.15" rpy="0 0 0"/>
    <axis xyz="0 0 1"/>
    <limit lower="-0.5" upper="0.5" effort="50" velocity="1.0"/>
  </joint>
  <joint name="spine2_joint" type="revolute">
    <parent link="spine1_link"/>
    <child link="spine2_link"/>
    <origin xyz="0 0 0.2" rpy="0 0 0"/>
    <axis xyz="0 0 1"/>
    <limit lower="-0.5" upper="0.5" effort="50" velocity="1.0"/>
  </joint>
  <joint name="neck_joint" type="revolute">
    <parent link="spine2_link"/>
    <child link="neck_link"/>
    <origin xyz="0 0 0.2" rpy="0 0 0"/>
    <axis xyz="0 0 1"/>
    <limit lower="-0.5" upper="0.5" effort="20" velocity="1.0"/>
  </joint>
  <joint name="head_joint" type="revolute">
    <parent link="neck_link"/>
    <child link="head_link"/>
    <origin xyz="0 0 0.1" rpy="0 0 0"/>
    <axis xyz="0 0 1"/>
    <limit lower="-1.0" upper="1.0" effort="20" velocity="1.0"/>
  </joint>

  <!-- Left Arm Joints -->
  <joint name="left_shoulder_joint" type="revolute">
    <parent link="spine2_link"/>
    <child link="left_shoulder_link"/>
    <origin xyz="0.1 0 0.18" rpy="0 0 0"/>
    <axis xyz="0 1 0"/>
    <limit lower="-1.5" upper="1.5" effort="50" velocity="1.5"/>
  </joint>
  <joint name="left_upper_arm_joint" type="revolute">
    <parent link="left_shoulder_link"/>
    <child link="left_upper_arm_link"/>
    <origin xyz="0 0 0" rpy="0 0 0"/>
    <axis xyz="1 0 0"/>
    <limit lower="-2.0" upper="2.0" effort="50" velocity="1.5"/>
  </joint>
  <joint name="left_forearm_joint" type="revolute">
    <parent link="left_upper_arm_link"/>
    <child link="left_forearm_link"/>
    <origin xyz="0 0 -0.25" rpy="0 0 0"/>
    <axis xyz="1 0 0"/>
    <limit lower="0" upper="2.0" effort="30" velocity="2.0"/>
  </joint>
  <joint name="left_hand_joint" type="revolute">
    <parent link="left_forearm_link"/>
    <child link="left_hand_link"/>
    <origin xyz="0 0 -0.25" rpy="0 0 0"/>
    <axis xyz="0 1 0"/>
    <limit lower="-0.5" upper="0.5" effort="20" velocity="1.0"/>
  </joint>

  <!-- Right Arm Joints -->
  <joint name="right_shoulder_joint" type="revolute">
    <parent link="spine2_link"/>
    <child link="right_shoulder_link"/>
    <origin xyz="-0.1 0 0.18" rpy="0 0 0"/>
    <axis xyz="0 1 0"/>
    <limit lower="-1.5" upper="1.5" effort="50" velocity="1.5"/>
  </joint>
  <joint name="right_upper_arm_joint" type="revolute">
    <parent link="right_shoulder_link"/>
    <child link="right_upper_arm_link"/>
    <origin xyz="0 0 0" rpy="0 0 0"/>
    <axis xyz="1 0 0"/>
    <limit lower="-2.0" upper="2.0" effort="50" velocity="1.5"/>
  </joint>
  <joint name="right_forearm_joint" type="revolute">
    <parent link="right_upper_arm_link"/>
    <child link="right_forearm_link"/>
    <origin xyz="0 0 -0.25" rpy="0 0 0"/>
    <axis xyz="1 0 0"/>
    <limit lower="0" upper="2.0" effort="30" velocity="2.0"/>
  </joint>
  <joint name="right_hand_joint" type="revolute">
    <parent link="right_forearm_link"/>
    <child link="right_hand_link"/>
    <origin xyz="0 0 -0.25" rpy="0 0 0"/>
    <axis xyz="0 1 0"/>
    <limit lower="-0.5" upper="0.5" effort="20" velocity="1.0"/>
  </joint>

  <!-- Left Leg Joints -->
  <joint name="left_hip_joint" type="revolute">
    <parent link="base_link"/>
    <child link="left_hip_link"/>
    <origin xyz="0.08 0 -0.15" rpy="0 0 0"/>
    <axis xyz="1 0 0"/>
    <limit lower="-1.5" upper="1.5" effort="80" velocity="2.0"/>
  </joint>
  <joint name="left_thigh_joint" type="revolute">
    <parent link="left_hip_link"/>
    <child link="left_thigh_link"/>
    <origin xyz="0 0 -0.08" rpy="0 0 0"/>
    <axis xyz="1 0 0"/>
    <limit lower="-2.0" upper="2.0" effort="100" velocity="2.0"/>
  </joint>
  <joint name="left_shin_joint" type="revolute">
    <parent link="left_thigh_link"/>
    <child link="left_shin_link"/>
    <origin xyz="0 0 -0.3" rpy="0 0 0"/>
    <axis xyz="1 0 0"/>
    <limit lower="0" upper="2.0" effort="80" velocity="2.0"/>
  </joint>
  <joint name="left_foot_joint" type="revolute">
    <parent link="left_shin_link"/>
    <child link="left_foot_link"/>
    <origin xyz="0 0 -0.3" rpy="0 0 0"/>
    <axis xyz="1 0 0"/>
    <limit lower="-0.5" upper="0.5" effort="50" velocity="1.0"/>
  </joint>

  <!-- Right Leg Joints -->
  <joint name="right_hip_joint" type="revolute">
    <parent link="base_link"/>
    <child link="right_hip_link"/>
    <origin xyz="-0.08 0 -0.15" rpy="0 0 0"/>
    <axis xyz="1 0 0"/>
    <limit lower="-1.5" upper="1.5" effort="80" velocity="2.0"/>
  </joint>
  <joint name="right_thigh_joint" type="revolute">
    <parent link="right_hip_link"/>
    <child link="right_thigh_link"/>
    <origin xyz="0 0 -0.08" rpy="0 0 0"/>
    <axis xyz="1 0 0"/>
    <limit lower="-2.0" upper="2.0" effort="100" velocity="2.0"/>
  </joint>
  <joint name="right_shin_joint" type="revolute">
    <parent link="right_thigh_link"/>
    <child link="right_shin_link"/>
    <origin xyz="0 0 -0.3" rpy="0 0 0"/>
    <axis xyz="1 0 0"/>
    <limit lower="0" upper="2.0" effort="80" velocity="2.0"/>
  </joint>
  <joint name="right_foot_joint" type="revolute">
    <parent link="right_shin_link"/>
    <child link="right_foot_link"/>
    <origin xyz="0 0 -0.3" rpy="0 0 0"/>
    <axis xyz="1 0 0"/>
    <limit lower="-0.5" upper="0.5" effort="50" velocity="1.0"/>
  </joint>

</robot>
